Workbook

Sheet Data_Harian
A1: Tahun | B1: Bulan | C1: Tanggal | D1: Tanggal (ISO) | E1: Curah Hujan (mm) | G1: Sumber: data/processed/hidrologi.db (src/build_db.py) <- Curah_Hujan_Sungai_Ambawang_BWSK_2012-2025.xlsx (BWSK). Sel kosong = data hilang.
A2: 2012 | B2: 1 | C2: 1 | D2: 2012-01-01 | E2: 0
A3: 2012 | B3: 1 | C3: 2 | D3: 2012-01-02 | E3: 0
A4: 2012 | B4: 1 | C4: 3 | D4: 2012-01-03 | E4: 0
A5: 2012 | B5: 1 | C5: 4 | D5: 2012-01-04 | E5: 80
A6: 2012 | B6: 1 | C6: 5 | D6: 2012-01-05 | E6: 0
A7: 2012 | B7: 1 | C7: 6 | D7: 2012-01-06 | E7: 0
A8: 2012 | B8: 1 | C8: 7 | D8: 2012-01-07 | E8: 43
A9: 2012 | B9: 1 | C9: 8 | D9: 2012-01-08 | E9: 33
A10: 2012 | B10: 1 | C10: 9 | D10: 2012-01-09 | E10: 1
A11: 2012 | B11: 1 | C11: 10 | D11: 2012-01-10 | E11: 56
A12: 2012 | B12: 1 | C12: 11 | D12: 2012-01-11 | E12: 0
A13: 2012 | B13: 1 | C13: 12 | D13: 2012-01-12 | E13: 12
... A731: 2013 | B731: 12 | C731: 30 | D731: 2013-12-30 | E731: 7
A732: 2013 | B732: 12 | C732: 31 | D732: 2013-12-31
A733: 2014 | B733: 1 | C733: 1 | D733: 2014-01-01 | E733: 0
A734: 2014 | B734: 1 | C734: 2 | D734: 2014-01-02 | E734: 11
A735: 2014 | B735: 1 | C735: 3 | D735: 2014-01-03 | E735: 0
A736: 2014 | B736: 1 | C736: 4 | D736: 2014-01-04 | E736: 0
A737: 2014 | B737: 1 | C737: 5 | D737: 2014-01-05 | E737: 0
A738: 2014 | B738: 1 | C738: 6 | D738: 2014-01-06 | E738: 6
A739: 2014 | B739: 1 | C739: 7 | D739: 2014-01-07 | E739: 0
A740: 2014 | B740: 1 | C740: 8 | D740: 2014-01-08 | E740: 10
A741: 2014 | B741: 1 | C741: 9 | D741: 2014-01-09 | E741: 0
A742: 2014 | B742: 1 | C742: 10 | D742: 2014-01-10 | E742: 2
A743: 2014 | B743: 1 | C743: 11 | D743: 2014-01-11 | E743: 10
A744: 2014 | B744: 1 | C744: 12 | D744: 2014-01-12 | E744: 0
... A2150: 2017 | B2150: 11 | C2150: 18 | D2150: 2017-11-18 | E2150: 0
A2151: 2017 | B2151: 11 | C2151: 19 | D2151: 2017-11-19
A2152: 2017 | B2152: 11 | C2152: 20 | D2152: 2017-11-20 | E2152: 0
A2153: 2017 | B2153: 11 | C2153: 21 | D2153: 2017-11-21 | E2153: 14
A2154: 2017 | B2154: 11 | C2154: 22 | D2154: 2017-11-22 | E2154: 0
A2155: 2017 | B2155: 11 | C2155: 23 | D2155: 2017-11-23 | E2155: 0
A2156: 2017 | B2156: 11 | C2156: 24 | D2156: 2017-11-24 | E2156: 8
A2157: 2017 | B2157: 11 | C2157: 25 | D2157: 2017-11-25 | E2157: 15
A2158: 2017 | B2158: 11 | C2158: 26 | D2158: 2017-11-26 | E2158: 0
A2159: 2017 | B2159: 11 | C2159: 27 | D2159: 2017-11-27 | E2159: 8
A2160: 2017 | B2160: 11 | C2160: 28 | D2160: 2017-11-28 | E2160: 0
A2161: 2017 | B2161: 11 | C2161: 29 | D2161: 2017-11-29 | E2161: 0
A2162: 2017 | B2162: 11 | C2162: 30 | D2162: 2017-11-30 | E2162: 11
...

Sheet Statistik_Tahunan
A1: STATISTIK CURAH HUJAN TAHUNAN (formula dari Data_Harian)
A2: Tahun | B2: Jumlah Hari | C2: Data Valid | D2: Data Hilang | E2: Total Curah Hujan (mm) | F2: X Maks Harian (mm) | G2: Hari Hujan (mm>0)
A3: 2012 | B3: =COUNTIFS(Data_Harian!$A$2:$A$5115,$A3) -> 366 | C3: =COUNTIFS(Data_Harian!$A$2:$A$5115,$A3,Data_Harian!$E$2:$E$5115,">=0") -> 366 | D3: =B3-C3 -> 0 | E3: =SUMIFS(Data_Harian!$E$2:$E$5115,Data_Harian!$A$2:$A$5115,$A3) -> 3109 | F3: =_xlfn.MAXIFS(Data_Harian!$E$2:$E$5115,Data_Harian!$A$2:$A$5115,$A3) -> 81 | G3: =COUNTIFS(Data_Harian!$A$2:$A$5115,$A3,Data_Harian!$E$2:$E$5115,">0") -> 142
A4: 2013 | B4: =COUNTIFS(Data_Harian!$A$2:$A$5115,$A4) -> 365 | C4: =COUNTIFS(Data_Harian!$A$2:$A$5115,$A4,Data_Harian!$E$2:$E$5115,">=0") -> 364 | D4: =B4-C4 -> 1 | E4: =SUMIFS(Data_Harian!$E$2:$E$5115,Data_Harian!$A$2:$A$5115,$A4) -> 2916 | F4: =_xlfn.MAXIFS(Data_Harian!$E$2:$E$5115,Data_Harian!$A$2:$A$5115,$A4) -> 120 | G4: =COUNTIFS(Data_Harian!$A$2:$A$5115,$A4,Data_Harian!$E$2:$E$5115,">0") -> 154
A5: 2014 | B5: =COUNTIFS(Data_Harian!$A$2:$A$5115,$A5) -> 365 | C5: =COUNTIFS(Data_Harian!$A$2:$A$5115,$A5,Data_Harian!$E$2:$E$5115,">=0") -> 365 | D5: =B5-C5 -> 0 | E5: =SUMIFS(Data_Harian!$E$2:$E$5115,Data_Harian!$A$2:$A$5115,$A5) -> 2386 | F5: =_xlfn.MAXIFS(Data_Harian!$E$2:$E$5115,Data_Harian!$A$2:$A$5115,$A5) -> 120 | G5: =COUNTIFS(Data_Harian!$A$2:$A$5115,$A5,Data_Harian!$E$2:$E$5115,">0") -> 123
A6: 2015 | B6: =COUNTIFS(Data_Harian!$A$2:$A$5115,$A6) -> 365 | C6: =COUNTIFS(Data_Harian!$A$2:$A$5115,$A6,Data_Harian!$E$2:$E$5115,">=0") -> 365 | D6: =B6-C6 -> 0 | E6: =SUMIFS(Data_Harian!$E$2:$E$5115,Data_Harian!$A$2:$A$5115,$A6) -> 2961 | F6: =_xlfn.MAXIFS(Data_Harian!$E$2:$E$5115,Data_Harian!$A$2:$A$5115,$A6) -> 91 | G6: =COUNTIFS(Data_Harian!$A$2:$A$5115,$A6,Data_Harian!$E$2:$E$5115,">0") -> 127
A7: 2016 | B7: =COUNTIFS(Data_Harian!$A$2:$A$5115,$A7) -> 366 | C7: =COUNTIFS(Data_Harian!$A$2:$A$5115,$A7,Data_Harian!$E$2:$E$5115,">=0") -> 366 | D7: =B7-C7 -> 0 | E7: =SUMIFS(Data_Harian!$E$2:$E$5115,Data_Harian!$A$2:$A$5115,$A7) -> 3228 | F7: =_xlfn.MAXIFS(Data_Harian!$E$2:$E$5115,Data_Harian!$A$2:$A$5115,$A7) -> 88 | G7: =COUNTIFS(Data_Harian!$A$2:$A$5115,$A7,Data_Harian!$E$2:$E$5115,">0") -> 145
A8: 2017 | B8: =COUNTIFS(Data_Harian!$A$2:$A$5115,$A8) -> 365 | C8: =COUNTIFS(Data_Harian!$A$2:$A$5115,$A8,Data_Harian!$E$2:$E$5115,">=0") -> 364 | D8: =B8-C8 -> 1 | E8: =SUMIFS(Data_Harian!$E$2:$E$5115,Data_Harian!$A$2:$A$5115,$A8) -> 2631 | F8: =_xlfn.MAXIFS(Data_Harian!$E$2:$E$5115,Data_Harian!$A$2:$A$5115,$A8) -> 86 | G8: =COUNTIFS(Data_Harian!$A$2:$A$5115,$A8,Data_Harian!$E$2:$E$5115,">0") -> 168
A9: 2018 | B9: =COUNTIFS(Data_Harian!$A$2:$A$5115,$A9) -> 365 | C9: =COUNTIFS(Data_Harian!$A$2:$A$5115,$A9,Data_Harian!$E$2:$E$5115,">=0") -> 365 | D9: =B9-C9 -> 0 | E9: =SUMIFS(Data_Harian!$E$2:$E$5115,Data_Harian!$A$2:$A$5115,$A9) -> 1654 | F9: =_xlfn.MAXIFS(Data_Harian!$E$2:$E$5115,Data_Harian!$A$2:$A$5115,$A9) -> 62 | G9: =COUNTIFS(Data_Harian!$A$2:$A$5115,$A9,Data_Harian!$E$2:$E$5115,">0") -> 155
A10: 2019 | B10: =COUNTIFS(Data_Harian!$A$2:$A$5115,$A10) -> 365 | C10: =COUNTIFS(Data_Harian!$A$2:$A$5115,$A10,Data_Harian!$E$2:$E$5115,">=0") -> 363 | D10: =B10-C10 -> 2 | E10: =SUMIFS(Data_Harian!$E$2:$E$5115,Data_Harian!$A$2:$A$5115,$A10) -> 2313 | F10: =_xlfn.MAXIFS(Data_Harian!$E$2:$E$5115,Data_Harian!$A$2:$A$5115,$A10) -> 88 | G10: =COUNTIFS(Data_Harian!$A$2:$A$5115,$A10,Data_Harian!$E$2:$E$5115,">0") -> 161
A11: 2020 | B11: =COUNTIFS(Data_Harian!$A$2:$A$5115,$A11) -> 366 | C11: =COUNTIFS(Data_Harian!$A$2:$A$5115,$A11,Data_Harian!$E$2:$E$5115,">=0") -> 366 | D11: =B11-C11 -> 0 | E11: =SUMIFS(Data_Harian!$E$2:$E$5115,Data_Harian!$A$2:$A$5115,$A11) -> 4189 | F11: =_xlfn.MAXIFS(Data_Harian!$E$2:$E$5115,Data_Harian!$A$2:$A$5115,$A11) -> 220 | G11: =COUNTIFS(Data_Harian!$A$2:$A$5115,$A11,Data_Harian!$E$2:$E$5115,">0") -> 192
A12: 2021 | B12: =COUNTIFS(Data_Harian!$A$2:$A$5115,$A12) -> 365 | C12: =COUNTIFS(Data_Harian!$A$2:$A$5115,$A12,Data_Harian!$E$2:$E$5115,">=0") -> 365 | D12: =B12-C12 -> 0 | E12: =SUMIFS(Data_Harian!$E$2:$E$5115,Data_Harian!$A$2:$A$5115,$A12) -> 3696 | F12: =_xlfn.MAXIFS(Data_Harian!$E$2:$E$5115,Data_Harian!$A$2:$A$5115,$A12) -> 151 | G12: =COUNTIFS(Data_Harian!$A$2:$A$5115,$A12,Data_Harian!$E$2:$E$5115,">0") -> 181
A13: 2022 | B13: =COUNTIFS(Data_Harian!$A$2:$A$5115,$A13) -> 365 | C13: =COUNTIFS(Data_Harian!$A$2:$A$5115,$A13,Data_Harian!$E$2:$E$5115,">=0") -> 365 | D13: =B13-C13 -> 0 | E13: =SUMIFS(Data_Harian!$E$2:$E$5115,Data_Harian!$A$2:$A$5115,$A13) -> 2926 | F13: =_xlfn.MAXIFS(Data_Harian!$E$2:$E$5115,Data_Harian!$A$2:$A$5115,$A13) -> 91 | G13: =COUNTIFS(Data_Harian!$A$2:$A$5115,$A13,Data_Harian!$E$2:$E$5115,">0") -> 220
A14: 2023 | B14: =COUNTIFS(Data_Harian!$A$2:$A$5115,$A14) -> 365 | C14: =COUNTIFS(Data_Harian!$A$2:$A$5115,$A14,Data_Harian!$E$2:$E$5115,">=0") -> 357 | D14: =B14-C14 -> 8 | E14: =SUMIFS(Data_Harian!$E$2:$E$5115,Data_Harian!$A$2:$A$5115,$A14) -> 3260 | F14: =_xlfn.MAXIFS(Data_Harian!$E$2:$E$5115,Data_Harian!$A$2:$A$5115,$A14) -> 100 | G14: =COUNTIFS(Data_Harian!$A$2:$A$5115,$A14,Data_Harian!$E$2:$E$5115,">0") -> 204
... A16: 2025 | B16: =COUNTIFS(Data_Harian!$A$2:$A$5115,$A16) -> 365 | C16: =COUNTIFS(Data_Harian!$A$2:$A$5115,$A16,Data_Harian!$E$2:$E$5115,">=0") -> 365 | D16: =B16-C16 -> 0 | E16: =SUMIFS(Data_Harian!$E$2:$E$5115,Data_Harian!$A$2:$A$5115,$A16) -> 3310 | F16: =_xlfn.MAXIFS(Data_Harian!$E$2:$E$5115,Data_Harian!$A$2:$A$5115,$A16) -> 100 | G16: =COUNTIFS(Data_Harian!$A$2:$A$5115,$A16,Data_Harian!$E$2:$E$5115,">0") -> 206
A17: TOTAL | E17: =SUM(E3:E16) -> 42290

Sheet Statistik
A1: STATISTIK DISTRIBUSI X MAKS TAHUNAN
A2: Nilai | B2: Satuan/Keterangan
A3: n (jumlah tahun) | B3: =COUNT(Statistik_Tahunan!$F$3:$F$16) -> 14 | C3: tahun
A4: X barat (rata-rata X maks) | B4: =AVERAGE(Statistik_Tahunan!$F$3:$F$16) -> 111.28571 | C4: mm
A5: S (simpangan baku, pembagi n-1) | B5: =STDEV(Statistik_Tahunan!$F$3:$F$16) -> 41.201995 | C5: mm
A6: Cv = S / X barat | B6: =B5/B4 -> 0.37023616
A7: Cs (rumus tesis [7]) | B7: =B3/((B3-1)*(B3-2))*SUMPRODUCT(((Statistik_Tahunan!$F$3:$F$16-B4)/B5)^3) -> 1.611465
A8: Ck (rumus tesis [8]) | B8: =(1/B3)*SUMPRODUCT(((Statistik_Tahunan!$F$3:$F$16-B4)/B5)^4) -> 3.8646731
A9: Rata-rata log10 X | B9: =SUMPRODUCT(LOG10(Statistik_Tahunan!$F$3:$F$16))/B3 -> 2.0233075
A10: S log10 | B10: =SQRT(SUMPRODUCT((LOG10(Statistik_Tahunan!$F$3:$F$16)-B9)^2)/(B3-1)) -> 0.14173952
A11: Cs log10 (rumus [15]) | B11: =B3/((B3-1)*(B3-2))*SUMPRODUCT(((LOG10(Statistik_Tahunan!$F$3:$F$16)-B9)/B10)^3) -> 0.83411797

Sheet Uji_Homogenitas
A1: UJI HOMOGENITAS DATA (Uji-t dua sampel)
A2: Nilai | B2: Keterangan
A3: n1 (7 tahun pertama) | B3: =COUNT(Statistik_Tahunan!$F$3:$F$9) -> 7 | C3: 2012-2018
A4: n2 (7 tahun terakhir) | B4: =COUNT(Statistik_Tahunan!$F$10:$F$16) -> 7 | C4: 2019-2025
A5: X barat 1 | B5: =AVERAGE(Statistik_Tahunan!$F$3:$F$9) -> 92.571429
A6: X barat 2 | B6: =AVERAGE(Statistik_Tahunan!$F$10:$F$16) -> 130
A7: S1 (pembagi n1) | B7: =SQRT(SUMPRODUCT((Statistik_Tahunan!$F$3:$F$9-B5)^2)/B3) -> 19.419115
A8: S2 (pembagi n2) | B8: =SQRT(SUMPRODUCT((Statistik_Tahunan!$F$10:$F$16-B6)^2)/B4) -> 45.553736
A9: sigma pooled | B9: =SQRT((B3*B7^2+B4*B8^2)/(B3+B4-2)) -> 37.821637
A10: t hitung | B10: =ABS(B5-B6)/(B9*SQRT(1/B3+1/B4)) -> 1.8513859
A11: dk = n1+n2-2 | B11: =B3+B4-2 -> 12
A12: t kritis (dua arah, alpha=5%) | B12: =INDEX(Koefisien!$C$5:$C$34,MATCH(MIN(B11,30),Koefisien!$A$5:$A$34,1)) -> 2.179 | C12: Tabel 2.2
A13: t kritis (satu arah, alpha=5%) | B13: =INDEX(Koefisien!$B$5:$B$34,MATCH(MIN(B11,30),Koefisien!$A$5:$A$34,1)) -> 1.782
A14: Kesimpulan (dua arah) | B14: =IF(B10<B12,"HOMOGEN","TIDAK HOMOGEN") -> HOMOGEN
A15: Kesimpulan (satu arah) | B15: =IF(B10<B13,"HOMOGEN","TIDAK HOMOGEN") -> TIDAK HOMOGEN

Sheet Uji_Konsistensi
A1: UJI KONSISTENSI DATA (Cumulative Deviation)
A2: Nilai | B2: Keterangan
A3: n | B3: =Statistik!B3 -> 14
A4: X barat | B4: =Statistik!B4 -> 111.28571
A5: Dy = SQRT(SUM(dev^2)/n) | B5: =SQRT(SUMPRODUCT($C$13:$C$26^2)/B3) -> 39.703236
A6: Q = maks |S**k| | B6: =MAX(MAX($E$13:$E$26),-MIN($E$13:$E$26)) -> 3.8859733
A7: Q / SQRT(n) | B7: =B6/SQRT(B3) -> 1.03857
A8: Kritik 95% (interpolasi Tabel 2.3) | B8: =Koefisien!$B$38+(B3-Koefisien!$A$38)/(Koefisien!$A$39-Koefisien!$A$38)*(Koefisien!$B$39-Koefisien!$B$38) -> 1.172
A9: Kritik 99% (interpolasi Tabel 2.3) | B9: =Koefisien!$C$38+(B3-Koefisien!$A$38)/(Koefisien!$A$39-Koefisien!$A$38)*(Koefisien!$C$39-Koefisien!$C$38) -> 1.342
A10: Kesimpulan (95%) | B10: =IF(B7<B8,"KONSISTEN","TIDAK KONSISTEN") -> KONSISTEN
A11: Kesimpulan (99%) | B11: =IF(B7<B9,"KONSISTEN","TIDAK KONSISTEN") -> KONSISTEN
A12: Tahun | B12: X (mm) | C12: Deviasi (X-Xbar) | D12: S**k (kumulatif) | E12: S**k / Dy
A13: =Statistik_Tahunan!A3 -> 2012 | B13: =Statistik_Tahunan!F3 -> 81 | C13: =B13-$B$4 -> -30.285714 | D13: =C13 -> -30.285714 | E13: =D13/$B$5 -> -0.76280217
A14: =Statistik_Tahunan!A4 -> 2013 | B14: =Statistik_Tahunan!F4 -> 120 | C14: =B14-$B$4 -> 8.7142857 | D14: =D13+C14 -> -21.571429 | E14: =D14/$B$5 -> -0.54331664
A15: =Statistik_Tahunan!A5 -> 2014 | B15: =Statistik_Tahunan!F5 -> 120 | C15: =B15-$B$4 -> 8.7142857 | D15: =D14+C15 -> -12.857143 | E15: =D15/$B$5 -> -0.32383111
A16: =Statistik_Tahunan!A6 -> 2015 | B16: =Statistik_Tahunan!F6 -> 91 | C16: =B16-$B$4 -> -20.285714 | D16: =D15+C16 -> -33.142857 | E16: =D16/$B$5 -> -0.83476463
A17: =Statistik_Tahunan!A7 -> 2016 | B17: =Statistik_Tahunan!F7 -> 88 | C17: =B17-$B$4 -> -23.285714 | D17: =D16+C17 -> -56.428571 | E17: =D17/$B$5 -> -1.4212588
A18: =Statistik_Tahunan!A8 -> 2017 | B18: =Statistik_Tahunan!F8 -> 86 | C18: =B18-$B$4 -> -25.285714 | D18: =D17+C18 -> -81.714286 | E18: =D18/$B$5 -> -2.0581266
A19: =Statistik_Tahunan!A9 -> 2018 | B19: =Statistik_Tahunan!F9 -> 62 | C19: =B19-$B$4 -> -49.285714 | D19: =D18+C19 -> -131 | E19: =D19/$B$5 -> -3.2994792
A20: =Statistik_Tahunan!A10 -> 2019 | B20: =Statistik_Tahunan!F10 -> 88 | C20: =B20-$B$4 -> -23.285714 | D20: =D19+C20 -> -154.28571 | E20: =D20/$B$5 -> -3.8859733
A21: =Statistik_Tahunan!A11 -> 2020 | B21: =Statistik_Tahunan!F11 -> 220 | C21: =B21-$B$4 -> 108.71429 | D21: =D20+C21 -> -45.571429 | E21: =D21/$B$5 -> -1.1478014
A22: =Statistik_Tahunan!A12 -> 2021 | B22: =Statistik_Tahunan!F12 -> 151 | C22: =B22-$B$4 -> 39.714286 | D22: =D21+C22 -> -5.8571429 | E22: =D22/$B$5 -> -0.14752306
A23: =Statistik_Tahunan!A13 -> 2022 | B23: =Statistik_Tahunan!F13 -> 91 | C23: =B23-$B$4 -> -20.285714 | D23: =D22+C23 -> -26.142857 | E23: =D23/$B$5 -> -0.65845659
A24: =Statistik_Tahunan!A14 -> 2023 | B24: =Statistik_Tahunan!F14 -> 100 | C24: =B24-$B$4 -> -11.285714 | D24: =D23+C24 -> -37.428571 | E24: =D24/$B$5 -> -0.94270834
A25: =Statistik_Tahunan!A15 -> 2024 | B25: =Statistik_Tahunan!F15 -> 160 | C25: =B25-$B$4 -> 48.714286 | D25: =D24+C25 -> 11.285714 | E25: =D25/$B$5 -> 0.28425175
A26: =Statistik_Tahunan!A16 -> 2025 | B26: =Statistik_Tahunan!F16 -> 100 | C26: =B26-$B$4 -> -11.285714 | D26: =D25+C26 -> -8.5265128e-14 | E26: =D26/$B$5 -> -2.1475612e-15

Sheet Frekuensi
A1: ANALISIS FREKUENSI CURAH HUJAN MAKSIMUM HARIAN TAHUNAN
A3: a Gumbel = S / 1,283 | B3: =Statistik!$B$5/1.283 -> 32.113792
A4: Xo Gumbel = X barat - 0,577.a | B4: =Statistik!$B$4-0.577*B3 -> 92.756056
A5: Cs log10 (dari sheet Statistik) | B5: =Statistik!$B$11 -> 0.83411797
A7: T (tahun) | B7: K Normal | C7: XT Normal (mm) | D7: Yp Gumbel | E7: XT Gumbel (mm) | F7: K LP3 | G7: XT LP3 (mm)
A8: 2 | B8: =INDEX(Koefisien!$B$44:$B$49,MATCH($A8,Koefisien!$A$44:$A$49,0)) -> 0 | C8: =Statistik!$B$4+B8*Statistik!$B$5 -> 111.28571 | D8: =INDEX(Koefisien!$B$53:$B$58,MATCH($A8,Koefisien!$A$53:$A$58,0)) -> 0.366 | E8: =$B$4+D8*$B$3 -> 104.5097 | F8: =INDEX(Koefisien!B$62:B$98,MIN(IFERROR(MATCH($B$5,Koefisien!$A$62:$A$98,1),1),36))+($B$5-INDEX(Koefisien!$A$62:$A$98,MIN(IFERROR(MATCH($B$5,Koefisien!$A$62:$A$98,1),1),36)))/(INDEX(Koefisien!$A$62:$A$98,MIN(IFERROR(MATCH($B$5,Koefisien!$A$62:$A$98,1),1),36)+1)-INDEX(Koefisien!$A$62:$A$98,MIN(IFERROR(MATCH($B$5,Koefisien!$A$62:$A$98,1),1),36)))*(INDEX(Koefisien!B$62:B$98,MIN(IFERROR(MATCH($B$5,Koefisien!$A$62:$A$98,1),1),36)+1)-INDEX(Koefisien!B$62:B$98,MIN(IFERROR(MATCH($B$5,Koefisien!$A$62:$A$98,1),1),36))) -> -0.13745888 | G8: =10^(Statistik!$B$9+F8*Statistik!$B$10) -> 100.88444
A9: 5 | B9: =INDEX(Koefisien!$B$44:$B$49,MATCH($A9,Koefisien!$A$44:$A$49,0)) -> 0.84 | C9: =Statistik!$B$4+B9*Statistik!$B$5 -> 145.89539 | D9: =INDEX(Koefisien!$B$53:$B$58,MATCH($A9,Koefisien!$A$53:$A$58,0)) -> 1.51 | E9: =$B$4+D9*$B$3 -> 141.24788 | F9: =INDEX(Koefisien!C$62:C$98,MIN(IFERROR(MATCH($B$5,Koefisien!$A$62:$A$98,1),1),36))+($B$5-INDEX(Koefisien!$A$62:$A$98,MIN(IFERROR(MATCH($B$5,Koefisien!$A$62:$A$98,1),1),36)))/(INDEX(Koefisien!$A$62:$A$98,MIN(IFERROR(MATCH($B$5,Koefisien!$A$62:$A$98,1),1),36)+1)-INDEX(Koefisien!$A$62:$A$98,MIN(IFERROR(MATCH($B$5,Koefisien!$A$62:$A$98,1),1),36)))*(INDEX(Koefisien!C$62:C$98,MIN(IFERROR(MATCH($B$5,Koefisien!$A$62:$A$98,1),1),36)+1)-INDEX(Koefisien!C$62:C$98,MIN(IFERROR(MATCH($B$5,Koefisien!$A$62:$A$98,1),1),36))) -> 0.77624702 | G9: =10^(Statistik!$B$9+F9*Statistik!$B$10) -> 135.93535
A10: 10 | B10: =INDEX(Koefisien!$B$44:$B$49,MATCH($A10,Koefisien!$A$44:$A$49,0)) -> 1.28 | C10: =Statistik!$B$4+B10*Statistik!$B$5 -> 164.02427 | D10: =INDEX(Koefisien!$B$53:$B$58,MATCH($A10,Koefisien!$A$53:$A$58,0)) -> 2.25 | E10: =$B$4+D10*$B$3 -> 165.01209 | F10: =INDEX(Koefisien!D$62:D$98,MIN(IFERROR(MATCH($B$5,Koefisien!$A$62:$A$98,1),1),36))+($B$5-INDEX(Koefisien!$A$62:$A$98,MIN(IFERROR(MATCH($B$5,Koefisien!$A$62:$A$98,1),1),36)))/(INDEX(Koefisien!$A$62:$A$98,MIN(IFERROR(MATCH($B$5,Koefisien!$A$62:$A$98,1),1),36)+1)-INDEX(Koefisien!$A$62:$A$98,MIN(IFERROR(MATCH($B$5,Koefisien!$A$62:$A$98,1),1),36)))*(INDEX(Koefisien!D$62:D$98,MIN(IFERROR(MATCH($B$5,Koefisien!$A$62:$A$98,1),1),36)+1)-INDEX(Koefisien!D$62:D$98,MIN(IFERROR(MATCH($B$5,Koefisien!$A$62:$A$98,1),1),36))) -> 1.3370235 | G10: =10^(Statistik!$B$9+F10*Statistik!$B$10) -> 163.23625
A11: 25 | B11: =INDEX(Koefisien!$B$44:$B$49,MATCH($A11,Koefisien!$A$44:$A$49,0)) -> 1.64 | C11: =Statistik!$B$4+B11*Statistik!$B$5 -> 178.85699 | D11: =INDEX(Koefisien!$B$53:$B$58,MATCH($A11,Koefisien!$A$53:$A$58,0)) -> 3.9 | E11: =$B$4+D11*$B$3 -> 217.99984 | F11: =INDEX(Koefisien!E$62:E$98,MIN(IFERROR(MATCH($B$5,Koefisien!$A$62:$A$98,1),1),36))+($B$5-INDEX(Koefisien!$A$62:$A$98,MIN(IFERROR(MATCH($B$5,Koefisien!$A$62:$A$98,1),1),36)))/(INDEX(Koefisien!$A$62:$A$98,MIN(IFERROR(MATCH($B$5,Koefisien!$A$62:$A$98,1),1),36)+1)-INDEX(Koefisien!$A$62:$A$98,MIN(IFERROR(MATCH($B$5,Koefisien!$A$62:$A$98,1),1),36)))*(INDEX(Koefisien!E$62:E$98,MIN(IFERROR(MATCH($B$5,Koefisien!$A$62:$A$98,1),1),36)+1)-INDEX(Koefisien!E$62:E$98,MIN(IFERROR(MATCH($B$5,Koefisien!$A$62:$A$98,1),1),36))) -> 2.0048236 | G11: =10^(Statistik!$B$9+F11*Statistik!$B$10) -> 202.98795
A12: 50 | B12: =INDEX(Koefisien!$B$44:$B$49,MATCH($A12,Koefisien!$A$44:$A$49,0)) -> 2.05 | C12: =Statistik!$B$4+B12*Statistik!$B$5 -> 195.7498 | D12: =INDEX(Koefisien!$B$53:$B$58,MATCH($A12,Koefisien!$A$53:$A$58,0)) -> 4.6 | E12: =$B$4+D12*$B$3 -> 240.4795 | F12: =INDEX(Koefisien!F$62:F$98,MIN(IFERROR(MATCH($B$5,Koefisien!$A$62:$A$98,1),1),36))+($B$5-INDEX(Koefisien!$A$62:$A$98,MIN(IFERROR(MATCH($B$5,Koefisien!$A$62:$A$98,1),1),36)))/(INDEX(Koefisien!$A$62:$A$98,MIN(IFERROR(MATCH($B$5,Koefisien!$A$62:$A$98,1),1),36)+1)-INDEX(Koefisien!$A$62:$A$98,MIN(IFERROR(MATCH($B$5,Koefisien!$A$62:$A$98,1),1),36)))*(INDEX(Koefisien!F$62:F$98,MIN(IFERROR(MATCH($B$5,Koefisien!$A$62:$A$98,1),1),36)+1)-INDEX(Koefisien!F$62:F$98,MIN(IFERROR(MATCH($B$5,Koefisien!$A$62:$A$98,1),1),36))) -> 2.4683531 | G12: =10^(Statistik!$B$9+F12*Statistik!$B$10) -> 236.14063
A13: 100 | B13: =INDEX(Koefisien!$B$44:$B$49,MATCH($A13,Koefisien!$A$44:$A$49,0)) -> 2.33 | C13: =Statistik!$B$4+B13*Statistik!$B$5 -> 207.28636 | D13: =INDEX(Koefisien!$B$53:$B$58,MATCH($A13,Koefisien!$A$53:$A$58,0)) -> 5.29 | E13: =$B$4+D13*$B$3 -> 262.63802 | F13: =INDEX(Koefisien!G$62:G$98,MIN(IFERROR(MATCH($B$5,Koefisien!$A$62:$A$98,1),1),36))+($B$5-INDEX(Koefisien!$A$62:$A$98,MIN(IFERROR(MATCH($B$5,Koefisien!$A$62:$A$98,1),1),36)))/(INDEX(Koefisien!$A$62:$A$98,MIN(IFERROR(MATCH($B$5,Koefisien!$A$62:$A$98,1),1),36)+1)-INDEX(Koefisien!$A$62:$A$98,MIN(IFERROR(MATCH($B$5,Koefisien!$A$62:$A$98,1),1),36)))*(INDEX(Koefisien!G$62:G$98,MIN(IFERROR(MATCH($B$5,Koefisien!$A$62:$A$98,1),1),36)+1)-INDEX(Koefisien!G$62:G$98,MIN(IFERROR(MATCH($B$5,Koefisien!$A$62:$A$98,1),1),36))) -> 2.9135179 | G13: =10^(Statistik!$B$9+F13*Statistik!$B$10) -> 273.06633
A15: Catatan: K Normal (Tabel 2.4), Yp Gumbel (Tabel 2.5), K LP3 (Tabel 2.6) di sheet Koefisien. XT Normal = Xbar + K.S ; XT Gumbel = Xo + Yp.a ; XT LP3 = 10^(rata2 log + K.S log).

Sheet Chi_Kuadrat
A1: UJI CHI-KUADRAT PEMILIHAN DISTRIBUSI
A2: Kelas dibatasi R2, R5, R10, R25 (peluang di sheet Koefisien baris 102-106, menjumlah 1,00 - keputusan 5 REVISI.md)
A6: Distribusi Normal
A7: Kelas | B7: Batas (mm) | C7: O | D7: E = n.p | E7: (O-E)^2/E
A8: x <= R2 | B8: =Frekuensi!$C$8 -> 111.28571 | C8: =COUNTIFS(Statistik_Tahunan!$F$3:$F$16,"<="&B8) -> 9 | D8: =Statistik!$B$3*Koefisien!$B$102 -> 7 | E8: =(C8-D8)^2/D8 -> 0.57142857
A9: R2 < x <= R5 | B9: =Frekuensi!$C$9 -> 145.89539 | C9: =COUNTIFS(Statistik_Tahunan!$F$3:$F$16,">"&B8,Statistik_Tahunan!$F$3:$F$16,"<="&B9) -> 2 | D9: =Statistik!$B$3*Koefisien!$B$103 -> 2.8 | E9: =(C9-D9)^2/D9 -> 0.22857143
A10: R5 < x <= R10 | B10: =Frekuensi!$C$10 -> 164.02427 | C10: =COUNTIFS(Statistik_Tahunan!$F$3:$F$16,">"&B9,Statistik_Tahunan!$F$3:$F$16,"<="&B10) -> 2 | D10: =Statistik!$B$3*Koefisien!$B$104 -> 1.4 | E10: =(C10-D10)^2/D10 -> 0.25714286
A11: R10 < x <= R25 | B11: =Frekuensi!$C$11 -> 178.85699 | C11: =COUNTIFS(Statistik_Tahunan!$F$3:$F$16,">"&B10,Statistik_Tahunan!$F$3:$F$16,"<="&B11) -> 0 | D11: =Statistik!$B$3*Koefisien!$B$105 -> 0.84 | E11: =(C11-D11)^2/D11 -> 0.84
A12: x > R25 | B12: - | C12: =COUNTIFS(Statistik_Tahunan!$F$3:$F$16,">"&B11) -> 1 | D12: =Statistik!$B$3*Koefisien!$B$106 -> 1.96 | E12: =(C12-D12)^2/D12 -> 0.47020408
A13: chi-kuadrat hitung | B13: =SUM(E8:E12) -> 2.3673469
A14: dk = 5-1-P | B14: =4-2 -> 2
A15: chi-kuadrat kritis | B15: =INDEX(Koefisien!$B$110:$B$111,MATCH(B14,Koefisien!$A$110:$A$111,0)) -> 5.991
A16: Kesimpulan | B16: =IF(B13<=B15,"LOLOS","GAGAL") -> LOLOS
A17: chi2 kandidat (999 bila gagal) | B17: =IF(B16="LOLOS",B13,999) -> 2.3673469
A19: Distribusi Gumbel
A20: Kelas | B20: Batas (mm) | C20: O | D20: E = n.p | E20: (O-E)^2/E
A21: x <= R2 | B21: =Frekuensi!$E$8 -> 104.5097 | C21: =COUNTIFS(Statistik_Tahunan!$F$3:$F$16,"<="&B21) -> 9 | D21: =Statistik!$B$3*Koefisien!$B$102 -> 7 | E21: =(C21-D21)^2/D21 -> 0.57142857
A22: R2 < x <= R5 | B22: =Frekuensi!$E$9 -> 141.24788 | C22: =COUNTIFS(Statistik_Tahunan!$F$3:$F$16,">"&B8,Statistik_Tahunan!$F$3:$F$16,"<="&B22) -> 2 | D22: =Statistik!$B$3*Koefisien!$B$103 -> 2.8 | E22: =(C22-D22)^2/D22 -> 0.22857143
A23: R5 < x <= R10 | B23: =Frekuensi!$E$10 -> 165.01209 | C23: =COUNTIFS(Statistik_Tahunan!$F$3:$F$16,">"&B9,Statistik_Tahunan!$F$3:$F$16,"<="&B23) -> 2 | D23: =Statistik!$B$3*Koefisien!$B$104 -> 1.4 | E23: =(C23-D23)^2/D23 -> 0.25714286
A24: R10 < x <= R25 | B24: =Frekuensi!$E$11 -> 217.99984 | C24: =COUNTIFS(Statistik_Tahunan!$F$3:$F$16,">"&B10,Statistik_Tahunan!$F$3:$F$16,"<="&B24) -> 0 | D24: =Statistik!$B$3*Koefisien!$B$105 -> 0.84 | E24: =(C24-D24)^2/D24 -> 0.84
A25: x > R25 | B25: - | C25: =COUNTIFS(Statistik_Tahunan!$F$3:$F$16,">"&B11) -> 1 | D25: =Statistik!$B$3*Koefisien!$B$106 -> 1.96 | E25: =(C25-D25)^2/D25 -> 0.47020408
A26: chi-kuadrat hitung | B26: =SUM(E21:E25) -> 2.3673469
A27: dk = 5-1-P | B27: =4-2 -> 2
A28: chi-kuadrat kritis | B28: =INDEX(Koefisien!$B$110:$B$111,MATCH(B27,Koefisien!$A$110:$A$111,0)) -> 5.991
A29: Kesimpulan | B29: =IF(B26<=B28,"LOLOS","GAGAL") -> LOLOS
A30: chi2 kandidat (999 bila gagal) | B30: =IF(B29="LOLOS",B26,999) -> 2.3673469
A32: Distribusi LP3
A33: Kelas | B33: Batas (mm) | C33: O | D33: E = n.p | E33: (O-E)^2/E
A34: x <= R2 | B34: =Frekuensi!$G$8 -> 100.88444 | C34: =COUNTIFS(Statistik_Tahunan!$F$3:$F$16,"<="&B34) -> 9 | D34: =Statistik!$B$3*Koefisien!$B$102 -> 7 | E34: =(C34-D34)^2/D34 -> 0.57142857
A35: R2 < x <= R5 | B35: =Frekuensi!$G$9 -> 135.93535 | C35: =COUNTIFS(Statistik_Tahunan!$F$3:$F$16,">"&B8,Statistik_Tahunan!$F$3:$F$16,"<="&B35) -> 2 | D35: =Statistik!$B$3*Koefisien!$B$103 -> 2.8 | E35: =(C35-D35)^2/D35 -> 0.22857143
A36: R5 < x <= R10 | B36: =Frekuensi!$G$10 -> 163.23625 | C36: =COUNTIFS(Statistik_Tahunan!$F$3:$F$16,">"&B9,Statistik_Tahunan!$F$3:$F$16,"<="&B36) -> 2 | D36: =Statistik!$B$3*Koefisien!$B$104 -> 1.4 | E36: =(C36-D36)^2/D36 -> 0.25714286
A37: R10 < x <= R25 | B37: =Frekuensi!$G$11 -> 202.98795 | C37: =COUNTIFS(Statistik_Tahunan!$F$3:$F$16,">"&B10,Statistik_Tahunan!$F$3:$F$16,"<="&B37) -> 0 | D37: =Statistik!$B$3*Koefisien!$B$105 -> 0.84 | E37: =(C37-D37)^2/D37 -> 0.84
A38: x > R25 | B38: - | C38: =COUNTIFS(Statistik_Tahunan!$F$3:$F$16,">"&B11) -> 1 | D38: =Statistik!$B$3*Koefisien!$B$106 -> 1.96 | E38: =(C38-D38)^2/D38 -> 0.47020408
A39: chi-kuadrat hitung | B39: =SUM(E34:E38) -> 2.3673469
A40: dk = 5-1-P | B40: =4-3 -> 1
A41: chi-kuadrat kritis | B41: =INDEX(Koefisien!$B$110:$B$111,MATCH(B40,Koefisien!$A$110:$A$111,0)) -> 3.841
A42: Kesimpulan | B42: =IF(B39<=B41,"LOLOS","GAGAL") -> LOLOS
A43: chi2 kandidat (999 bila gagal) | B43: =IF(B42="LOLOS",B39,999) -> 2.3673469
A45: Prioritas pemilihan saat kandidat seri: LP3 (SNI 2415:2016) > Gumbel > Normal
A46: chi2 kandidat terkecil | B46: =MIN(B17,B30,B43) -> 2.3673469
...

Sheet Debit_Rencana
A1: PERHITUNGAN DEBIT BANJIR RENCANA - RINGKASAN (tautan silang)
A2: Nilai desain dihitung pada sheet Hidrolika_Pipa (iterasi envelope, parameter site dari tabel parameter_desain). Sheet ini merangkum dengan tautan silang. Field lama to/td/tc/I/Q (parameter Lo=200, Ss=0,002, Ld=300) telah dihapus (keputusan 4 REVISI.md).
A3: Parameter | B3: Nilai | C3: Satuan | D3: Keterangan/Sumber
A4: Lo (panjang aliran atap) | B4: 8 | C4: m | D4: Panjang aliran permukaan ATAP titik terjauh (Tipe 36, atap 65 m2). Asumsi tipologi - WAJIB diverifikasi survei (Tesis 3.3.1)
A5: S_atap (kemiringan atap) | B5: 0.3 | C5: m/m | D5: Kemiringan atap (asumsi 30%) - masuk Kirpich utk to
A6: Ld (panjang pipa penyalur) | B6: 330 | C6: m | D6: Panjang pipa penyalur: unit terjauh ujung timur ke kolam rencana ujung barat laut (siteplan 1:1500, bentang 330,40 m)
A7: S_pipa (kemiringan pipa) | B7: 0.003 | C7: m/m | D7: Kemiringan pipa 0,30% (asumsi topografi datar - WAJIB diverifikasi waterpass)
A8: n Manning pipa | B8: 0.011 | C8: - | D8: Manning pipa (Tabel 2.8)
A9: C (koefisien limpasan) | B9: =Kawasan!$B$11 -> 0.8 | C9: - | D9: link sheet Kawasan (Tabel 2.7)
A10: A (luas atap) | B10: =Kawasan!$B$9 -> 10400 | C10: m2 | D10: link sheet Kawasan
A11: th (waktu konsentrasi tandon) | B11: =Kawasan!$B$15 -> 1 | C11: jam | D11: link sheet Kawasan (Tesis 3.4.3)
A14: HASIL PERHITUNGAN (semua tautan silang sheet Hidrolika_Pipa/Desain_Kolam)
A15: Besaran | B15: Nilai | C15: Satuan | D15: Rumus
A16: R24 curah hujan (T=10 th, dist. terpilih) | B16: =IF(Chi_Kuadrat!$B$47="LP3",Frekuensi!$G$10,IF(Chi_Kuadrat!$B$47="Gumbel",Frekuensi!$E$10,Frekuensi!$C$10)) -> 163.23625 | C16: mm | D16: XT distribusi terpilih (sheet Frekuensi/Chi_Kuadrat)
A17: to (waktu konsentrasi overland) [21] | B17: =Hidrolika_Pipa!$B$10 -> 0.15371711 | C17: menit | D17: tautan silang Hidrolika_Pipa (Kirpich pada atap)
A18: v pipa desain [39] | B18: =Hidrolika_Pipa!$B$58 -> 1.3930403 | C18: m/dtk | D18: tautan silang Hidrolika_Pipa (envelope)
A19: td (waktu alir pipa) [22] | B19: =Hidrolika_Pipa!$B$53 -> 3.2520493 | C19: menit | D19: tautan silang Hidrolika_Pipa (envelope)
A20: tc (waktu konsentrasi) [20] | B20: =Hidrolika_Pipa!$B$54 -> 0.056762774 | C20: jam | D20: tautan silang Hidrolika_Pipa (envelope)
A21: I (intensitas Mononobe) [19] | B21: =Hidrolika_Pipa!$B$52 -> 383.15143 | C21: mm/jam | D21: tautan silang Hidrolika_Pipa (pada Q desain)
A22: Q desain (Rasional) [23] | B22: =Hidrolika_Pipa!$B$51 -> 0.88621393 | C22: m3/dtk | D22: tautan silang Hidrolika_Pipa (maksimum iterasi)
A23: Va (volume atenuasi, th=1 jam) [32] | B23: =Desain_Kolam!$B$13 -> 3190.3701 | C23: m3 | D23: Va = Q . th
A25: Catatan: R24 dari XT T=10 tahun distribusi terpilih (uji chi-kuadrat). Parameter site (Lo, S_atap, Ld, S_pipa) masih asumsi - ganti dengan data lapangan.

Sheet Kawasan
A1: PARAMETER KAWASAN & KEBUTUHAN AIR (sumber: tabel kawasan di data/processed/hidrologi.db)
A2: Kunci | B2: Nilai | C2: Satuan | D2: Sumber
A3: nama_kawasan | B3: Rajawali Residence | C3: - | D3: Tesis 1.1/3.2
A4: lokasi | B4: Jl. Wonodadi 2, Kec. Sungai Raya, Kab. Kubu Raya | C4: - | D4: Tesis 3.2
A5: luas_kawasan | B5: 28800 | C5: m2 | D5: Tesis 1.1 (2,88 ha); siteplan 330,40 x 85,78 m
A6: jumlah_unit | B6: 160 | C6: unit | D6: Tesis 1.1/3.2 (Tipe 36)
A7: jiwa_per_unit | B7: 4 | C7: jiwa | D7: Tesis 1.1
A8: luas_atap_per_unit | B8: 65 | C8: m2 | D8: Tesis 1.1
A9: luas_atap_total | B9: 10400 | C9: m2 | D9: Tesis 1.1 (36,1% luas kawasan)
A10: q_kebutuhan_air | B10: 120 | C10: liter/jiwa/hari | D10: SNI 03-7065-2005 (Tabel 2.1)
A11: C_atap | B11: 0.8 | C11: - | D11: Tabel 2.7 (atap logam/seng, rentang 0,70-0,90)
A12: fraksi_desain | B12: 0.65 | C12: - | D12: Tesis 3.4.1 (titik tengah 60-70% kebutuhan non-potabel)
A13: fraksi_diuji | B13: 1.00; 0.70; 0.65; 0.60; 0.50 | C13: - | D13: Tesis 3.4.1
A14: freeboard | B14: 0.5 | C14: m | D14: Tesis 2.7 (Putra dkk., 2023)
A15: th_durasi_efektif | B15: 1 | C15: jam | D15: Tesis 3.4.3 (sensitivitas 0,5-3 jam)
A17: PERHITUNGAN TURUNAN (formula hidup)
A18: Besaran | B18: Nilai | C18: Satuan | D18: Rumus
A19: Q kebutuhan total [36] | B19: =B6*B7*B10 -> 76800 | C19: liter/hari | D19: jumlah_unit x jiwa x q
A20: Q harian | B20: =B19/1000 -> 76.8 | C20: m3/hari | D20: Q kebutuhan / 1000
A21: Luas atap total | B21: =B9/1000000 -> 0.0104 | C21: km2
A22: Rasio luas atap / luas kawasan | B22: =B9/B5 -> 0.36111111
A24: KEBUTUHAN AIR PER FRAKSI (Tesis 3.4.1)
A25: Fraksi f | B25: Q x f (m3/hari) | C25: Kebutuhan (liter/hari)
A26: 1 | B26: =$B$20*A26 -> 76.8 | C26: =A26*$B$19 -> 76800
A27: 0.7 | B27: =$B$20*A27 -> 53.76 | C27: =A27*$B$19 -> 53760
A28: 0.65 | B28: =$B$20*A28 -> 49.92 | C28: =A28*$B$19 -> 49920 | D28: <- fraksi desain
A29: 0.6 | B29: =$B$20*A29 -> 46.08 | C29: =A29*$B$19 -> 46080
A30: 0.5 | B30: =$B$20*A30 -> 38.4 | C30: =A30*$B$19 -> 38400

Sheet Evaporasi
A1: EVAPORASI MUKA AIR (PENMAN 1948) BULANAN
A2: Sumber: NOAA ISD Supadio (T, titik embun->RH, angin, tekanan) + NASA POWER CERES (Rs); agregasi harian 2012-2025 oleh src/evaporasi_penman.py. Evaporasi muka air terbuka - BUKAN ET0 rumput (keputusan 1 & 10 REVISI.md).
A4: Bulan | B4: Evaporasi E0 (mm/bulan) | C4: E0 (mm/hari) | D4: T (oC) | E4: RH (%) | F4: u2 (m/s) | G4: Rs (MJ/m2/hari) | H4: Keterangan
A5: 1 | B5: 149.98 | C5: 4.838 | D5: 26.98 | E5: 84.1 | F5: 1.31 | G5: 17.5 | H5: Penman (1948) muka air - NOAA ISD Supadio (T, Td, u, P) + NASA POWER CERES (Rs)
A6: 2 | B6: 148.64 | C6: 5.257 | D6: 27.08 | E6: 82.7 | F6: 1.29 | G6: 19.06 | H6: Penman (1948) muka air - NOAA ISD Supadio (T, Td, u, P) + NASA POWER CERES (Rs)
A7: 3 | B7: 166.18 | C7: 5.361 | D7: 27.39 | E7: 82.5 | F7: 1.19 | G7: 19.38 | H7: Penman (1948) muka air - NOAA ISD Supadio (T, Td, u, P) + NASA POWER CERES (Rs)
A8: 4 | B8: 157.75 | C8: 5.258 | D8: 27.54 | E8: 83.5 | F8: 1.14 | G8: 19.12 | H8: Penman (1948) muka air - NOAA ISD Supadio (T, Td, u, P) + NASA POWER CERES (Rs)
A9: 5 | B9: 158.35 | C9: 5.108 | D9: 27.89 | E9: 83.3 | F9: 1.1 | G9: 18.57 | H9: Penman (1948) muka air - NOAA ISD Supadio (T, Td, u, P) + NASA POWER CERES (Rs)
A10: 6 | B10: 150.17 | C10: 5.006 | D10: 27.68 | E10: 82.1 | F10: 1.17 | G10: 18.29 | H10: Penman (1948) muka air - NOAA ISD Supadio (T, Td, u, P) + NASA POWER CERES (Rs)
A11: 7 | B11: 160.84 | C11: 5.188 | D11: 27.51 | E11: 80.7 | F11: 1.32 | G11: 18.86 | H11: Penman (1948) muka air - NOAA ISD Supadio (T, Td, u, P) + NASA POWER CERES (Rs)
A12: 8 | B12: 161.16 | C12: 5.199 | D12: 27.38 | E12: 80.5 | F12: 1.38 | G12: 18.65 | H12: Penman (1948) muka air - NOAA ISD Supadio (T, Td, u, P) + NASA POWER CERES (Rs)
A13: 9 | B13: 159.21 | C13: 5.307 | D13: 27.4 | E13: 80.6 | F13: 1.3 | G13: 18.97 | H13: Penman (1948) muka air - NOAA ISD Supadio (T, Td, u, P) + NASA POWER CERES (Rs)
A14: 10 | B14: 151.5 | C14: 4.887 | D14: 27.12 | E14: 83.7 | F14: 1.15 | G14: 17.62 | H14: Penman (1948) muka air - NOAA ISD Supadio (T, Td, u, P) + NASA POWER CERES (Rs)
A15: 11 | B15: 142.3 | C15: 4.743 | D15: 26.91 | E15: 85.5 | F15: 1.15 | G15: 17.34 | H15: Penman (1948) muka air - NOAA ISD Supadio (T, Td, u, P) + NASA POWER CERES (Rs)
A16: 12 | B16: 145.07 | C16: 4.68 | D16: 26.92 | E16: 85.2 | F16: 1.27 | G16: 17.01 | H16: Penman (1948) muka air - NOAA ISD Supadio (T, Td, u, P) + NASA POWER CERES (Rs)
A17: TOTAL SETAHUN | B17: =SUM(B5:B16) -> 1851.15
A18: RATA-RATA | B18: =AVERAGE(B5:B16) -> 154.2625 | C18: dipakai sheet Neraca_Air (INDEX/MATCH kolom bulan)

Sheet Hidrolika_Pipa
A1: HIDROLIKA PIPA INDUK & PER UNIT - ITERASI ENVELOPE (MANNING ALIRAN PENUH)
A2: Aturan envelope: iterasi v<->td<->tc<->I<->Q<->D (12x, seed v=1 m/dtk) ber-osilasi karena umpan balik positif + pembulatan diameter diskrit; Q desain = maksimum iterasi (konservatif), D teoritis dihitung dari Q tsb lalu dibulatkan ke atas ke pipa komersial. Pipa diperlakukan sebagai saluran bulat PENUH terisi (Manning aliran penuh [29][30][38][39]), bukan aliran terbuka.
A4: Parameter | B4: Nilai | C4: Satuan | D4: Sumber/Keterangan
A5: Lo (panjang aliran atap) | B5: 8 | C5: m | D5: Panjang aliran permukaan ATAP titik terjauh (Tipe 36, atap 65 m2). Asumsi tipologi - WAJIB diverifikasi survei (Tesis 3.3.1)
A6: S_atap (kemiringan atap) | B6: 0.3 | C6: m/m | D6: Kemiringan atap (asumsi 30%) - masuk Kirpich utk to
A7: Ld (panjang pipa penyalur) | B7: 330 | C7: m | D7: Panjang pipa penyalur: unit terjauh ujung timur ke kolam rencana ujung barat laut (siteplan 1:1500, bentang 330,40 m)
A8: S_pipa (kemiringan pipa) | B8: 0.003 | C8: m/m | D8: Kemiringan pipa 0,30% (asumsi topografi datar - WAJIB diverifikasi waterpass)
A9: n Manning pipa | B9: 0.011 | C9: - | D9: Manning pipa (Tabel 2.8)
A10: to (Kirpich pada atap) [21] | B10: =0.0195*(B5/SQRT(B6))^0.77 -> 0.15371711 | C10: menit | D10: to = 0,0195.(Lo/SQRT(S))^0,77
A11: A atap total | B11: =Kawasan!$B$9 -> 10400 | C11: m2 | D11: link sheet Kawasan
A12: C (koefisien limpasan) | B12: =Kawasan!$B$11 -> 0.8 | D12: link sheet Kawasan (Tabel 2.7)
A13: A (luas atap) | B13: =B11/1000000 -> 0.0104 | C13: km2
A14: R24 curah hujan rencana (T=10 th) | B14: =IF(Chi_Kuadrat!$B$47="LP3",Frekuensi!$G$10,IF(Chi_Kuadrat!$B$47="Gumbel",Frekuensi!$E$10,Frekuensi!$C$10)) -> 163.23625 | C14: mm | D14: XT distribusi terpilih (sheet Frekuensi/Chi_Kuadrat)
A16: ITERASI v<->td<->tc<->I<->Q<->D - pipa induk (envelope)
A17: i | B17: v masuk (m/dtk) | C17: td (menit) | D17: tc (jam) | E17: I (mm/jam) | F17: Q (m3/dtk) | G17: D teor (m) | H17: D kom (mm) | I17: A pipa (m2) | J17: v keluar (m/dtk)
A18: 1 | B18: 1 | C18: =$B$7/(60*B18) -> 5.5 | D18: =($B$10+C18)/60 -> 0.094228619 | E18: =($B$14/24)*(24/D18)^(2/3) -> 273.29036 | F18: =0.278*$B$12*E18*$B$13 -> 0.63210966 | G18: =(F18*$B$9/(0.312*SQRT($B$8)))^(3/8) -> 0.71375836 | H18: =INDEX($B$33:$B$47,MIN(COUNTIF($B$33:$B$47,"<"&G18*1000)+1,15)) -> 750 | I18: =INDEX($C$33:$C$47,MATCH(H18,$B$33:$B$47,0)) -> 0.44178647 | J18: =F18/I18 -> 1.4308036
A19: 2 | B19: =J18 -> 1.4308036 | C19: =$B$7/(60*B19) -> 3.8439937 | D19: =($B$10+C19)/60 -> 0.066628514 | E19: =($B$14/24)*(24/D19)^(2/3) -> 344.32834 | F19: =0.278*$B$12*E19*$B$13 -> 0.79641768 | G19: =(F19*$B$9/(0.312*SQRT($B$8)))^(3/8) -> 0.77836246 | H19: =INDEX($B$33:$B$47,MIN(COUNTIF($B$33:$B$47,"<"&G19*1000)+1,15)) -> 800 | I19: =INDEX($C$33:$C$47,MATCH(H19,$B$33:$B$47,0)) -> 0.50265482 | J19: =F19/I19 -> 1.5844226
A20: 3 | B20: =J19 -> 1.5844226 | C20: =$B$7/(60*B20) -> 3.471296 | D20: =($B$10+C20)/60 -> 0.060416886 | E20: =($B$14/24)*(24/D20)^(2/3) -> 367.54228 | F20: =0.278*$B$12*E20*$B$13 -> 0.85011058 | G20: =(F20*$B$9/(0.312*SQRT($B$8)))^(3/8) -> 0.79764075 | H20: =INDEX($B$33:$B$47,MIN(COUNTIF($B$33:$B$47,"<"&G20*1000)+1,15)) -> 800 | I20: =INDEX($C$33:$C$47,MATCH(H20,$B$33:$B$47,0)) -> 0.50265482 | J20: =F20/I20 -> 1.6912413
A21: 4 | B21: =J20 -> 1.6912413 | C21: =$B$7/(60*B21) -> 3.2520493 | D21: =($B$10+C21)/60 -> 0.056762774 | E21: =($B$14/24)*(24/D21)^(2/3) -> 383.15143 | F21: =0.278*$B$12*E21*$B$13 -> 0.88621393 | G21: =(F21*$B$9/(0.312*SQRT($B$8)))^(3/8) -> 0.81017906 | H21: =INDEX($B$33:$B$47,MIN(COUNTIF($B$33:$B$47,"<"&G21*1000)+1,15)) -> 900 | I21: =INDEX($C$33:$C$47,MATCH(H21,$B$33:$B$47,0)) -> 0.63617251 | J21: =F21/I21 -> 1.3930403
A22: 5 | B22: =J21 -> 1.3930403 | C22: =$B$7/(60*B22) -> 3.9481988 | D22: =($B$10+C22)/60 -> 0.068365266 | E22: =($B$14/24)*(24/D22)^(2/3) -> 338.47182 | F22: =0.278*$B$12*E22*$B$13 -> 0.78287178 | G22: =(F22*$B$9/(0.312*SQRT($B$8)))^(3/8) -> 0.77337128 | H22: =INDEX($B$33:$B$47,MIN(COUNTIF($B$33:$B$47,"<"&G22*1000)+1,15)) -> 800 | I22: =INDEX($C$33:$C$47,MATCH(H22,$B$33:$B$47,0)) -> 0.50265482 | J22: =F22/I22 -> 1.5574739
A23: 6 | B23: =J22 -> 1.5574739 | C23: =$B$7/(60*B23) -> 3.5313593 | D23: =($B$10+C23)/60 -> 0.06141794 | E23: =($B$14/24)*(24/D23)^(2/3) -> 363.53762 | F23: =0.278*$B$12*E23*$B$13 -> 0.84084797 | G23: =(F23*$B$9/(0.312*SQRT($B$8)))^(3/8) -> 0.79437049 | H23: =INDEX($B$33:$B$47,MIN(COUNTIF($B$33:$B$47,"<"&G23*1000)+1,15)) -> 800 | I23: =INDEX($C$33:$C$47,MATCH(H23,$B$33:$B$47,0)) -> 0.50265482 | J23: =F23/I23 -> 1.6728139
A24: 7 | B24: =J23 -> 1.6728139 | C24: =$B$7/(60*B24) -> 3.2878732 | D24: =($B$10+C24)/60 -> 0.057359839 | E24: =($B$14/24)*(24/D24)^(2/3) -> 380.48795 | F24: =0.278*$B$12*E24*$B$13 -> 0.88005341 | G24: =(F24*$B$9/(0.312*SQRT($B$8)))^(3/8) -> 0.80806247 | H24: =INDEX($B$33:$B$47,MIN(COUNTIF($B$33:$B$47,"<"&G24*1000)+1,15)) -> 900 | I24: =INDEX($C$33:$C$47,MATCH(H24,$B$33:$B$47,0)) -> 0.63617251 | J24: =F24/I24 -> 1.3833565
A25: 8 | B25: =J24 -> 1.3833565 | C25: =$B$7/(60*B25) -> 3.9758369 | D25: =($B$10+C25)/60 -> 0.0688259 | E25: =($B$14/24)*(24/D25)^(2/3) -> 336.95993 | F25: =0.278*$B$12*E25*$B$13 -> 0.77937483 | G25: =(F25*$B$9/(0.312*SQRT($B$8)))^(3/8) -> 0.77207402 | H25: =INDEX($B$33:$B$47,MIN(COUNTIF($B$33:$B$47,"<"&G25*1000)+1,15)) -> 800 | I25: =INDEX($C$33:$C$47,MATCH(H25,$B$33:$B$47,0)) -> 0.50265482 | J25: =F25/I25 -> 1.550517
A26: 9 | B26: =J25 -> 1.550517 | C26: =$B$7/(60*B26) -> 3.547204 | D26: =($B$10+C26)/60 -> 0.061682019 | E26: =($B$14/24)*(24/D26)^(2/3) -> 362.49927 | F26: =0.278*$B$12*E26*$B$13 -> 0.83844631 | G26: =(F26*$B$9/(0.312*SQRT($B$8)))^(3/8) -> 0.79351889 | H26: =INDEX($B$33:$B$47,MIN(COUNTIF($B$33:$B$47,"<"&G26*1000)+1,15)) -> 800 | I26: =INDEX($C$33:$C$47,MATCH(H26,$B$33:$B$47,0)) -> 0.50265482 | J26: =F26/I26 -> 1.6680359
A27: 10 | B27: =J26 -> 1.6680359 | C27: =$B$7/(60*B27) -> 3.2972911 | D27: =($B$10+C27)/60 -> 0.057516803 | E27: =($B$14/24)*(24/D27)^(2/3) -> 379.7954 | F27: =0.278*$B$12*E27*$B$13 -> 0.87845156 | G27: =(F27*$B$9/(0.312*SQRT($B$8)))^(3/8) -> 0.8075106 | H27: =INDEX($B$33:$B$47,MIN(COUNTIF($B$33:$B$47,"<"&G27*1000)+1,15)) -> 900 | I27: =INDEX($C$33:$C$47,MATCH(H27,$B$33:$B$47,0)) -> 0.63617251 | J27: =F27/I27 -> 1.3808386
A28: 11 | B28: =J27 -> 1.3808386 | C28: =$B$7/(60*B28) -> 3.9830868 | D28: =($B$10+C28)/60 -> 0.068946732 | E28: =($B$14/24)*(24/D28)^(2/3) -> 336.56612 | F28: =0.278*$B$12*E28*$B$13 -> 0.77846398 | G28: =(F28*$B$9/(0.312*SQRT($B$8)))^(3/8) -> 0.77173553 | H28: =INDEX($B$33:$B$47,MIN(COUNTIF($B$33:$B$47,"<"&G28*1000)+1,15)) -> 800 | I28: =INDEX($C$33:$C$47,MATCH(H28,$B$33:$B$47,0)) -> 0.50265482 | J28: =F28/I28 -> 1.5487049
A29: 12 | B29: =J28 -> 1.5487049 | C29: =$B$7/(60*B29) -> 3.5513545 | D29: =($B$10+C29)/60 -> 0.061751193 | E29: =($B$14/24)*(24/D29)^(2/3) -> 362.2285 | F29: =0.278*$B$12*E29*$B$13 -> 0.83782004 | G29: =(F29*$B$9/(0.312*SQRT($B$8)))^(3/8) -> 0.79329657 | H29: =INDEX($B$33:$B$47,MIN(COUNTIF($B$33:$B$47,"<"&G29*1000)+1,15)) -> 800 | I29: =INDEX($C$33:$C$47,MATCH(H29,$B$33:$B$47,0)) -> 0.50265482 | J29: =F29/I29 -> 1.66679
A31: TABEL PIPA STANDAR (tabel pipa_standar di hidrologi.db)
A32: Label | B32: D (mm) | C32: A (m2)
A33: 4" (DN110) | B33: 110 | C33: =PI()*(B33/1000)^2/4 -> 0.0095033178
A34: 6" (DN160) | B34: 160 | C34: =PI()*(B34/1000)^2/4 -> 0.020106193
A35: 8" (DN200) | B35: 200 | C35: =PI()*(B35/1000)^2/4 -> 0.031415927
A36: 10" (DN250) | B36: 250 | C36: =PI()*(B36/1000)^2/4 -> 0.049087385
A37: 12" (DN315) | B37: 315 | C37: =PI()*(B37/1000)^2/4 -> 0.077931133
A38: 14" (DN355) | B38: 355 | C38: =PI()*(B38/1000)^2/4 -> 0.098979804
A39: 16" (DN400) | B39: 400 | C39: =PI()*(B39/1000)^2/4 -> 0.12566371
A40: 18" (DN450) | B40: 450 | C40: =PI()*(B40/1000)^2/4 -> 0.15904313
A41: 20" (DN500) | B41: 500 | C41: =PI()*(B41/1000)^2/4 -> 0.19634954
A42: 24" (DN600) | B42: 600 | C42: =PI()*(B42/1000)^2/4 -> 0.28274334
A43: 30" (DN750) | B43: 750 | C43: =PI()*(B43/1000)^2/4 -> 0.44178647
...

Sheet Neraca_Air
A1: NERACA AIR BULANAN - 5 FRAKSI KEBUTUHAN (Rippl [27], 2012-2025)
A2: E = evaporasi Penman muka air x luas kolam (Desain_Kolam B9, titik tetap iterasi Vs<->Ap); hujan langsung di permukaan kolam (P x Ap) dimasukkan sebagai pemasukan (keputusan 1 REVISI.md); kolom N-O = simulasi tampungan terbatas V_desain [26][28].
A4: Fraksi f = 1.00
A5: Tahun | B5: Bulan | C5: R (mm) | D5: n hari | E5: E0 (mm) | F5: Supply atap (m3) [24] | G5: Hujan kolam (m3) | H5: Demand (m3) [25] | I5: Evaporasi E (m3) | J5: Net (m3) | K5: K kumulatif (m3) | L5: Sp (m3) | M5: Defisit (m3) | N5: S (m3) [26] | O5: Terpenuhi
A6: 2012 | B6: 1 | C6: 349 | D6: 31 | E6: =INDEX(Evaporasi!$B$5:$B$16,MATCH(B6,Evaporasi!$A$5:$A$16,0)) -> 149.98 | F6: =Kawasan!$B$11*Kawasan!$B$9*C6/1000 -> 2903.68 | G6: =C6*Desain_Kolam!$B$9/1000 -> 1847.0825 | H6: =Kawasan!$B$26*D6 -> 2380.8 | I6: =E6*Desain_Kolam!$B$9/1000 -> 793.76915 | J6: =F6+G6-H6-I6 -> 1576.1934 | K6: =J6 -> 1576.1934 | L6: =MAX(0,K6) -> 1576.1934 | M6: =L6-K6 -> 0 | N6: =MIN(Desain_Kolam!$B$21,MAX(0,F6+G6-H6-I6)) -> 1576.1934 | O6: =IF(F6+G6-I6>=H6,1,0) -> 1
A7: 2012 | B7: 2 | C7: 340 | D7: 29 | E7: =INDEX(Evaporasi!$B$5:$B$16,MATCH(B7,Evaporasi!$A$5:$A$16,0)) -> 148.64 | F7: =Kawasan!$B$11*Kawasan!$B$9*C7/1000 -> 2828.8 | G7: =C7*Desain_Kolam!$B$9/1000 -> 1799.45 | H7: =Kawasan!$B$26*D7 -> 2227.2 | I7: =E7*Desain_Kolam!$B$9/1000 -> 786.6772 | J7: =F7+G7-H7-I7 -> 1614.3728 | K7: =K6+J7 -> 3190.5662 | L7: =MAX(L6,K7) -> 3190.5662 | M7: =L7-K7 -> 0 | N7: =MIN(Desain_Kolam!$B$21,MAX(0,N6+F7+G7-H7-I7)) -> 3190.5662 | O7: =IF(N6+F7+G7-I7>=H7,1,0) -> 1
A8: 2012 | B8: 3 | C8: 244 | D8: 31 | E8: =INDEX(Evaporasi!$B$5:$B$16,MATCH(B8,Evaporasi!$A$5:$A$16,0)) -> 166.18 | F8: =Kawasan!$B$11*Kawasan!$B$9*C8/1000 -> 2030.08 | G8: =C8*Desain_Kolam!$B$9/1000 -> 1291.37 | H8: =Kawasan!$B$26*D8 -> 2380.8 | I8: =E8*Desain_Kolam!$B$9/1000 -> 879.50765 | J8: =F8+G8-H8-I8 -> 61.14235 | K8: =K7+J8 -> 3251.7085 | L8: =MAX(L7,K8) -> 3251.7085 | M8: =L8-K8 -> 0 | N8: =MIN(Desain_Kolam!$B$21,MAX(0,N7+F8+G8-H8-I8)) -> 3251.7085 | O8: =IF(N7+F8+G8-I8>=H8,1,0) -> 1
A9: 2012 | B9: 4 | C9: 282 | D9: 30 | E9: =INDEX(Evaporasi!$B$5:$B$16,MATCH(B9,Evaporasi!$A$5:$A$16,0)) -> 157.75 | F9: =Kawasan!$B$11*Kawasan!$B$9*C9/1000 -> 2346.24 | G9: =C9*Desain_Kolam!$B$9/1000 -> 1492.485 | H9: =Kawasan!$B$26*D9 -> 2304 | I9: =E9*Desain_Kolam!$B$9/1000 -> 834.89188 | J9: =F9+G9-H9-I9 -> 699.83312 | K9: =K8+J9 -> 3951.5416 | L9: =MAX(L8,K9) -> 3951.5416 | M9: =L9-K9 -> 0 | N9: =MIN(Desain_Kolam!$B$21,MAX(0,N8+F9+G9-H9-I9)) -> 3951.5416 | O9: =IF(N8+F9+G9-I9>=H9,1,0) -> 1
A10: 2012 | B10: 5 | C10: 319 | D10: 31 | E10: =INDEX(Evaporasi!$B$5:$B$16,MATCH(B10,Evaporasi!$A$5:$A$16,0)) -> 158.35 | F10: =Kawasan!$B$11*Kawasan!$B$9*C10/1000 -> 2654.08 | G10: =C10*Desain_Kolam!$B$9/1000 -> 1688.3075 | H10: =Kawasan!$B$26*D10 -> 2380.8 | I10: =E10*Desain_Kolam!$B$9/1000 -> 838.06737 | J10: =F10+G10-H10-I10 -> 1123.5201 | K10: =K9+J10 -> 5075.0617 | L10: =MAX(L9,K10) -> 5075.0617 | M10: =L10-K10 -> 0 | N10: =MIN(Desain_Kolam!$B$21,MAX(0,N9+F10+G10-H10-I10)) -> 5075.0617 | O10: =IF(N9+F10+G10-I10>=H10,1,0) -> 1
A11: 2012 | B11: 6 | C11: 107 | D11: 30 | E11: =INDEX(Evaporasi!$B$5:$B$16,MATCH(B11,Evaporasi!$A$5:$A$16,0)) -> 150.17 | F11: =Kawasan!$B$11*Kawasan!$B$9*C11/1000 -> 890.24 | G11: =C11*Desain_Kolam!$B$9/1000 -> 566.2975 | H11: =Kawasan!$B$26*D11 -> 2304 | I11: =E11*Desain_Kolam!$B$9/1000 -> 794.77472 | J11: =F11+G11-H11-I11 -> -1642.2372 | K11: =K10+J11 -> 3432.8245 | L11: =MAX(L10,K11) -> 5075.0617 | M11: =L11-K11 -> 1642.2372 | N11: =MIN(Desain_Kolam!$B$21,MAX(0,N10+F11+G11-H11-I11)) -> 3432.8245 | O11: =IF(N10+F11+G11-I11>=H11,1,0) -> 1
A12: 2012 | B12: 7 | C12: 133 | D12: 31 | E12: =INDEX(Evaporasi!$B$5:$B$16,MATCH(B12,Evaporasi!$A$5:$A$16,0)) -> 160.84 | F12: =Kawasan!$B$11*Kawasan!$B$9*C12/1000 -> 1106.56 | G12: =C12*Desain_Kolam!$B$9/1000 -> 703.9025 | H12: =Kawasan!$B$26*D12 -> 2380.8 | I12: =E12*Desain_Kolam!$B$9/1000 -> 851.2457 | J12: =F12+G12-H12-I12 -> -1421.5832 | K12: =K11+J12 -> 2011.2413 | L12: =MAX(L11,K12) -> 5075.0617 | M12: =L12-K12 -> 3063.8204 | N12: =MIN(Desain_Kolam!$B$21,MAX(0,N11+F12+G12-H12-I12)) -> 2011.2413 | O12: =IF(N11+F12+G12-I12>=H12,1,0) -> 1
A13: 2012 | B13: 8 | C13: 105 | D13: 31 | E13: =INDEX(Evaporasi!$B$5:$B$16,MATCH(B13,Evaporasi!$A$5:$A$16,0)) -> 161.16 | F13: =Kawasan!$B$11*Kawasan!$B$9*C13/1000 -> 873.6 | G13: =C13*Desain_Kolam!$B$9/1000 -> 555.7125 | H13: =Kawasan!$B$26*D13 -> 2380.8 | I13: =E13*Desain_Kolam!$B$9/1000 -> 852.9393 | J13: =F13+G13-H13-I13 -> -1804.4268 | K13: =K12+J13 -> 206.81453 | L13: =MAX(L12,K13) -> 5075.0617 | M13: =L13-K13 -> 4868.2472 | N13: =MIN(Desain_Kolam!$B$21,MAX(0,N12+F13+G13-H13-I13)) -> 206.81453 | O13: =IF(N12+F13+G13-I13>=H13,1,0) -> 1
A14: 2012 | B14: 9 | C14: 174 | D14: 30 | E14: =INDEX(Evaporasi!$B$5:$B$16,MATCH(B14,Evaporasi!$A$5:$A$16,0)) -> 159.21 | F14: =Kawasan!$B$11*Kawasan!$B$9*C14/1000 -> 1447.68 | G14: =C14*Desain_Kolam!$B$9/1000 -> 920.895 | H14: =Kawasan!$B$26*D14 -> 2304 | I14: =E14*Desain_Kolam!$B$9/1000 -> 842.61892 | J14: =F14+G14-H14-I14 -> -778.04392 | K14: =K13+J14 -> -571.2294 | L14: =MAX(L13,K14) -> 5075.0617 | M14: =L14-K14 -> 5646.2912 | N14: =MIN(Desain_Kolam!$B$21,MAX(0,N13+F14+G14-H14-I14)) -> 0 | O14: =IF(N13+F14+G14-I14>=H14,1,0) -> 0
A15: 2012 | B15: 10 | C15: 436 | D15: 31 | E15: =INDEX(Evaporasi!$B$5:$B$16,MATCH(B15,Evaporasi!$A$5:$A$16,0)) -> 151.5 | F15: =Kawasan!$B$11*Kawasan!$B$9*C15/1000 -> 3627.52 | G15: =C15*Desain_Kolam!$B$9/1000 -> 2307.53 | H15: =Kawasan!$B$26*D15 -> 2380.8 | I15: =E15*Desain_Kolam!$B$9/1000 -> 801.81375 | J15: =F15+G15-H15-I15 -> 2752.4363 | K15: =K14+J15 -> 2181.2069 | L15: =MAX(L14,K15) -> 5075.0617 | M15: =L15-K15 -> 2893.8549 | N15: =MIN(Desain_Kolam!$B$21,MAX(0,N14+F15+G15-H15-I15)) -> 2752.4363 | O15: =IF(N14+F15+G15-I15>=H15,1,0) -> 1
A16: 2012 | B16: 11 | C16: 323 | D16: 30 | E16: =INDEX(Evaporasi!$B$5:$B$16,MATCH(B16,Evaporasi!$A$5:$A$16,0)) -> 142.3 | F16: =Kawasan!$B$11*Kawasan!$B$9*C16/1000 -> 2687.36 | G16: =C16*Desain_Kolam!$B$9/1000 -> 1709.4775 | H16: =Kawasan!$B$26*D16 -> 2304 | I16: =E16*Desain_Kolam!$B$9/1000 -> 753.12275 | J16: =F16+G16-H16-I16 -> 1339.7148 | K16: =K15+J16 -> 3520.9216 | L16: =MAX(L15,K16) -> 5075.0617 | M16: =L16-K16 -> 1554.1401 | N16: =MIN(Desain_Kolam!$B$21,MAX(0,N15+F16+G16-H16-I16)) -> 4092.151 | O16: =IF(N15+F16+G16-I16>=H16,1,0) -> 1
A17: 2012 | B17: 12 | C17: 297 | D17: 31 | E17: =INDEX(Evaporasi!$B$5:$B$16,MATCH(B17,Evaporasi!$A$5:$A$16,0)) -> 145.07 | F17: =Kawasan!$B$11*Kawasan!$B$9*C17/1000 -> 2471.04 | G17: =C17*Desain_Kolam!$B$9/1000 -> 1571.8725 | H17: =Kawasan!$B$26*D17 -> 2380.8 | I17: =E17*Desain_Kolam!$B$9/1000 -> 767.78297 | J17: =F17+G17-H17-I17 -> 894.32952 | K17: =K16+J17 -> 4415.2511 | L17: =MAX(L16,K17) -> 5075.0617 | M17: =L17-K17 -> 659.81062 | N17: =MIN(Desain_Kolam!$B$21,MAX(0,N16+F17+G17-H17-I17)) -> 4986.4805 | O17: =IF(N16+F17+G17-I17>=H17,1,0) -> 1
A18: 2013 | B18: 1 | C18: 141 | D18: 31 | E18: =INDEX(Evaporasi!$B$5:$B$16,MATCH(B18,Evaporasi!$A$5:$A$16,0)) -> 149.98 | F18: =Kawasan!$B$11*Kawasan!$B$9*C18/1000 -> 1173.12 | G18: =C18*Desain_Kolam!$B$9/1000 -> 746.2425 | H18: =Kawasan!$B$26*D18 -> 2380.8 | I18: =E18*Desain_Kolam!$B$9/1000 -> 793.76915 | J18: =F18+G18-H18-I18 -> -1255.2067 | K18: =K17+J18 -> 3160.0445 | L18: =MAX(L17,K18) -> 5075.0617 | M18: =L18-K18 -> 1915.0173 | N18: =MIN(Desain_Kolam!$B$21,MAX(0,N17+F18+G18-H18-I18)) -> 3731.2739 | O18: =IF(N17+F18+G18-I18>=H18,1,0) -> 1
... A173: 2025 | B173: 12 | C173: 140 | D173: 31 | E173: =INDEX(Evaporasi!$B$5:$B$16,MATCH(B173,Evaporasi!$A$5:$A$16,0)) -> 145.07 | F173: =Kawasan!$B$11*Kawasan!$B$9*C173/1000 -> 1164.8 | G173: =C173*Desain_Kolam!$B$9/1000 -> 740.95 | H173: =Kawasan!$B$26*D173 -> 2380.8 | I173: =E173*Desain_Kolam!$B$9/1000 -> 767.78297 | J173: =F173+G173-H173-I173 -> -1242.833 | K173: =K172+J173 -> 45756.466 | L173: =MAX(L172,K173) -> 46999.299 | M173: =L173-K173 -> 1242.833 | N173: =MIN(Desain_Kolam!$B$21,MAX(0,N172+F173+G173-H173-I173)) -> 14580.734 | O173: =IF(N172+F173+G173-I173>=H173,1,0) -> 1
A174: Vs fraksi 1.00 (m3) [27] | E174: =MAX(M6:M173) -> 36252.367
A175: Reliability (%) [28] | E175: =100*SUM(O6:O173)/COUNT(O6:O173) -> 88.690476
A176: Bulan terpenuhi (dari 168) | E176: =SUM(O6:O173) -> 149
A177: Total net kumulatif (m3) | E177: =K173 -> 45756.466
A179: Fraksi f = 0.70
A180: Tahun | B180: Bulan | C180: R (mm) | D180: n hari | E180: E0 (mm) | F180: Supply atap (m3) [24] | G180: Hujan kolam (m3) | H180: Demand (m3) [25] | I180: Evaporasi E (m3) | J180: Net (m3) | K180: K kumulatif (m3) | L180: Sp (m3) | M180: Defisit (m3) | N180: S (m3) [26] | O180: Terpenuhi
A181: 2012 | B181: 1 | C181: 349 | D181: 31 | E181: =INDEX(Evaporasi!$B$5:$B$16,MATCH(B181,Evaporasi!$A$5:$A$16,0)) -> 149.98 | F181: =Kawasan!$B$11*Kawasan!$B$9*C181/1000 -> 2903.68 | G181: =C181*Desain_Kolam!$B$9/1000 -> 1847.0825 | H181: =Kawasan!$B$27*D181 -> 1666.56 | I181: =E181*Desain_Kolam!$B$9/1000 -> 793.76915 | J181: =F181+G181-H181-I181 -> 2290.4333 | K181: =J181 -> 2290.4333 | L181: =MAX(0,K181) -> 2290.4333 | M181: =L181-K181 -> 0 | N181: =MIN(Desain_Kolam!$B$21,MAX(0,F181+G181-H181-I181)) -> 2290.4333 | O181: =IF(F181+G181-I181>=H181,1,0) -> 1
A182: 2012 | B182: 2 | C182: 340 | D182: 29 | E182: =INDEX(Evaporasi!$B$5:$B$16,MATCH(B182,Evaporasi!$A$5:$A$16,0)) -> 148.64 | F182: =Kawasan!$B$11*Kawasan!$B$9*C182/1000 -> 2828.8 | G182: =C182*Desain_Kolam!$B$9/1000 -> 1799.45 | H182: =Kawasan!$B$27*D182 -> 1559.04 | I182: =E182*Desain_Kolam!$B$9/1000 -> 786.6772 | J182: =F182+G182-H182-I182 -> 2282.5328 | K182: =K181+J182 -> 4572.9662 | L182: =MAX(L181,K182) -> 4572.9662 | M182: =L182-K182 -> 0 | N182: =MIN(Desain_Kolam!$B$21,MAX(0,N181+F182+G182-H182-I182)) -> 4572.9662 | O182: =IF(N181+F182+G182-I182>=H182,1,0) -> 1
A183: 2012 | B183: 3 | C183: 244 | D183: 31 | E183: =INDEX(Evaporasi!$B$5:$B$16,MATCH(B183,Evaporasi!$A$5:$A$16,0)) -> 166.18 | F183: =Kawasan!$B$11*Kawasan!$B$9*C183/1000 -> 2030.08 | G183: =C183*Desain_Kolam!$B$9/1000 -> 1291.37 | H183: =Kawasan!$B$27*D183 -> 1666.56 | I183: =E183*Desain_Kolam!$B$9/1000 -> 879.50765 | J183: =F183+G183-H183-I183 -> 775.38235 | K183: =K182+J183 -> 5348.3485 | L183: =MAX(L182,K183) -> 5348.3485 | M183: =L183-K183 -> 0 | N183: =MIN(Desain_Kolam!$B$21,MAX(0,N182+F183+G183-H183-I183)) -> 5348.3485 | O183: =IF(N182+F183+G183-I183>=H183,1,0) -> 1
A184: 2012 | B184: 4 | C184: 282 | D184: 30 | E184: =INDEX(Evaporasi!$B$5:$B$16,MATCH(B184,Evaporasi!$A$5:$A$16,0)) -> 157.75 | F184: =Kawasan!$B$11*Kawasan!$B$9*C184/1000 -> 2346.24 | G184: =C184*Desain_Kolam!$B$9/1000 -> 1492.485 | H184: =Kawasan!$B$27*D184 -> 1612.8 | I184: =E184*Desain_Kolam!$B$9/1000 -> 834.89188 | J184: =F184+G184-H184-I184 -> 1391.0331 | K184: =K183+J184 -> 6739.3816 | L184: =MAX(L183,K184) -> 6739.3816 | M184: =L184-K184 -> 0 | N184: =MIN(Desain_Kolam!$B$21,MAX(0,N183+F184+G184-H184-I184)) -> 6739.3816 | O184: =IF(N183+F184+G184-I184>=H184,1,0) -> 1
A185: 2012 | B185: 5 | C185: 319 | D185: 31 | E185: =INDEX(Evaporasi!$B$5:$B$16,MATCH(B185,Evaporasi!$A$5:$A$16,0)) -> 158.35 | F185: =Kawasan!$B$11*Kawasan!$B$9*C185/1000 -> 2654.08 | G185: =C185*Desain_Kolam!$B$9/1000 -> 1688.3075 | H185: =Kawasan!$B$27*D185 -> 1666.56 | I185: =E185*Desain_Kolam!$B$9/1000 -> 838.06737 | J185: =F185+G185-H185-I185 -> 1837.7601 | K185: =K184+J185 -> 8577.1418 | L185: =MAX(L184,K185) -> 8577.1418 | M185: =L185-K185 -> 0 | N185: =MIN(Desain_Kolam!$B$21,MAX(0,N184+F185+G185-H185-I185)) -> 8577.1418 | O185: =IF(N184+F185+G185-I185>=H185,1,0) -> 1
A186: 2012 | B186: 6 | C186: 107 | D186: 30 | E186: =INDEX(Evaporasi!$B$5:$B$16,MATCH(B186,Evaporasi!$A$5:$A$16,0)) -> 150.17 | F186: =Kawasan!$B$11*Kawasan!$B$9*C186/1000 -> 890.24 | G186: =C186*Desain_Kolam!$B$9/1000 -> 566.2975 | H186: =Kawasan!$B$27*D186 -> 1612.8 | I186: =E186*Desain_Kolam!$B$9/1000 -> 794.77472 | J186: =F186+G186-H186-I186 -> -951.03723 | K186: =K185+J186 -> 7626.1045 | L186: =MAX(L185,K186) -> 8577.1418 | M186: =L186-K186 -> 951.03723 | N186: =MIN(Desain_Kolam!$B$21,MAX(0,N185+F186+G186-H186-I186)) -> 7626.1045 | O186: =IF(N185+F186+G186-I186>=H186,1,0) -> 1
A187: 2012 | B187: 7 | C187: 133 | D187: 31 | E187: =INDEX(Evaporasi!$B$5:$B$16,MATCH(B187,Evaporasi!$A$5:$A$16,0)) -> 160.84 | F187: =Kawasan!$B$11*Kawasan!$B$9*C187/1000 -> 1106.56 | G187: =C187*Desain_Kolam!$B$9/1000 -> 703.9025 | H187: =Kawasan!$B$27*D187 -> 1666.56 | I187: =E187*Desain_Kolam!$B$9/1000 -> 851.2457 | J187: =F187+G187-H187-I187 -> -707.3432 | K187: =K186+J187 -> 6918.7613 | L187: =MAX(L186,K187) -> 8577.1418 | M187: =L187-K187 -> 1658.3804 | N187: =MIN(Desain_Kolam!$B$21,MAX(0,N186+F187+G187-H187-I187)) -> 6918.7613 | O187: =IF(N186+F187+G187-I187>=H187,1,0) -> 1
A188: 2012 | B188: 8 | C188: 105 | D188: 31 | E188: =INDEX(Evaporasi!$B$5:$B$16,MATCH(B188,Evaporasi!$A$5:$A$16,0)) -> 161.16 | F188: =Kawasan!$B$11*Kawasan!$B$9*C188/1000 -> 873.6 | G188: =C188*Desain_Kolam!$B$9/1000 -> 555.7125 | H188: =Kawasan!$B$27*D188 -> 1666.56 | I188: =E188*Desain_Kolam!$B$9/1000 -> 852.9393 | J188: =F188+G188-H188-I188 -> -1090.1868 | K188: =K187+J188 -> 5828.5745 | L188: =MAX(L187,K188) -> 8577.1418 | M188: =L188-K188 -> 2748.5672 | N188: =MIN(Desain_Kolam!$B$21,MAX(0,N187+F188+G188-H188-I188)) -> 5828.5745 | O188: =IF(N187+F188+G188-I188>=H188,1,0) -> 1
A189: 2012 | B189: 9 | C189: 174 | D189: 30 | E189: =INDEX(Evaporasi!$B$5:$B$16,MATCH(B189,Evaporasi!$A$5:$A$16,0)) -> 159.21 | F189: =Kawasan!$B$11*Kawasan!$B$9*C189/1000 -> 1447.68 | G189: =C189*Desain_Kolam!$B$9/1000 -> 920.895 | H189: =Kawasan!$B$27*D189 -> 1612.8 | I189: =E189*Desain_Kolam!$B$9/1000 -> 842.61892 | J189: =F189+G189-H189-I189 -> -86.843925 | K189: =K188+J189 -> 5741.7306 | L189: =MAX(L188,K189) -> 8577.1418 | M189: =L189-K189 -> 2835.4111 | N189: =MIN(Desain_Kolam!$B$21,MAX(0,N188+F189+G189-H189-I189)) -> 5741.7306 | O189: =IF(N188+F189+G189-I189>=H189,1,0) -> 1
A190: 2012 | B190: 10 | C190: 436 | D190: 31 | E190: =INDEX(Evaporasi!$B$5:$B$16,MATCH(B190,Evaporasi!$A$5:$A$16,0)) -> 151.5 | F190: =Kawasan!$B$11*Kawasan!$B$9*C190/1000 -> 3627.52 | G190: =C190*Desain_Kolam!$B$9/1000 -> 2307.53 | H190: =Kawasan!$B$27*D190 -> 1666.56 | I190: =E190*Desain_Kolam!$B$9/1000 -> 801.81375 | J190: =F190+G190-H190-I190 -> 3466.6762 | K190: =K189+J190 -> 9208.4068 | L190: =MAX(L189,K190) -> 9208.4068 | M190: =L190-K190 -> 0 | N190: =MIN(Desain_Kolam!$B$21,MAX(0,N189+F190+G190-H190-I190)) -> 9208.4069 | O190: =IF(N189+F190+G190-I190>=H190,1,0) -> 1
A191: 2012 | B191: 11 | C191: 323 | D191: 30 | E191: =INDEX(Evaporasi!$B$5:$B$16,MATCH(B191,Evaporasi!$A$5:$A$16,0)) -> 142.3 | F191: =Kawasan!$B$11*Kawasan!$B$9*C191/1000 -> 2687.36 | G191: =C191*Desain_Kolam!$B$9/1000 -> 1709.4775 | H191: =Kawasan!$B$27*D191 -> 1612.8 | I191: =E191*Desain_Kolam!$B$9/1000 -> 753.12275 | J191: =F191+G191-H191-I191 -> 2030.9147 | K191: =K190+J191 -> 11239.322 | L191: =MAX(L190,K191) -> 11239.322 | M191: =L191-K191 -> 0 | N191: =MIN(Desain_Kolam!$B$21,MAX(0,N190+F191+G191-H191-I191)) -> 11239.322 | O191: =IF(N190+F191+G191-I191>=H191,1,0) -> 1
A192: 2012 | B192: 12 | C192: 297 | D192: 31 | E192: =INDEX(Evaporasi!$B$5:$B$16,MATCH(B192,Evaporasi!$A$5:$A$16,0)) -> 145.07 | F192: =Kawasan!$B$11*Kawasan!$B$9*C192/1000 -> 2471.04 | G192: =C192*Desain_Kolam!$B$9/1000 -> 1571.8725 | H192: =Kawasan!$B$27*D192 -> 1666.56 | I192: =E192*Desain_Kolam!$B$9/1000 -> 767.78297 | J192: =F192+G192-H192-I192 -> 1608.5695 | K192: =K191+J192 -> 12847.891 | L192: =MAX(L191,K192) -> 12847.891 | M192: =L192-K192 -> 0 | N192: =MIN(Desain_Kolam!$B$21,MAX(0,N191+F192+G192-H192-I192)) -> 12847.891 | O192: =IF(N191+F192+G192-I192>=H192,1,0) -> 1
A193: 2013 | B193: 1 | C193: 141 | D193: 31 | E193: =INDEX(Evaporasi!$B$5:$B$16,MATCH(B193,Evaporasi!$A$5:$A$16,0)) -> 149.98 | F193: =Kawasan!$B$11*Kawasan!$B$9*C193/1000 -> 1173.12 | G193: =C193*Desain_Kolam!$B$9/1000 -> 746.2425 | H193: =Kawasan!$B$27*D193 -> 1666.56 | I193: =E193*Desain_Kolam!$B$9/1000 -> 793.76915 | J193: =F193+G193-H193-I193 -> -540.96665 | K193: =K192+J193 -> 12306.924 | L193: =MAX(L192,K193) -> 12847.891 | M193: =L193-K193 -> 540.96665 | N193: =MIN(Desain_Kolam!$B$21,MAX(0,N192+F193+G193-H193-I193)) -> 12306.924 | O193: =IF(N192+F193+G193-I193>=H193,1,0) -> 1
... A348: 2025 | B348: 12 | C348: 140 | D348: 31 | E348: =INDEX(Evaporasi!$B$5:$B$16,MATCH(B348,Evaporasi!$A$5:$A$16,0)) -> 145.07 | F348: =Kawasan!$B$11*Kawasan!$B$9*C348/1000 -> 1164.8 | G348: =C348*Desain_Kolam!$B$9/1000 -> 740.95 | H348: =Kawasan!$B$27*D348 -> 1666.56 | I348: =E348*Desain_Kolam!$B$9/1000 -> 767.78297 | J348: =F348+G348-H348-I348 -> -528.59298 | K348: =K347+J348 -> 163583.03 | L348: =MAX(L347,K348) -> 164111.62 | M348: =L348-K348 -> 528.59298 | N348: =MIN(Desain_Kolam!$B$21,MAX(0,N347+F348+G348-H348-I348)) -> 15294.974 | O348: =IF(N347+F348+G348-I348>=H348,1,0) -> 1
A349: Vs fraksi 0.70 (m3) [27] | E349: =MAX(M181:M348) -> 18741.967
A350: Reliability (%) [28] | E350: =100*SUM(O181:O348)/COUNT(O181:O348) -> 98.809524
...

Sheet Desain_Kolam
A1: DESAIN KOLAM RETENSI - DIMENSI, FREEBOARD & SENSITIVITAS
A2: Urutan: Va [32] -> neraca (E Penman + hujan kolam pada Ap) -> Vs [27] -> V desain [33] -> dimensi [34] -> iterasi Vs<->Ap sampai titik tetap. B9 = Ap hasil iterasi (tabel hasil_desain, src/analisis_desain.py); blok baris 28-35 merangkum iterasi, blok 37-42 memverifikasi titik tetap secara live. Dimensi dibulatkan ke atas kelipatan 0,5 m.
A4: Parameter | B4: Nilai | C4: Satuan | D4: Sumber/Keterangan
A5: he (kedalaman efektif kolam) | B5: 3 | C5: m | D5: Kedalaman efektif kolam (asumsi desain)
A6: hf (freeboard) | B6: =Kawasan!$B$14 -> 0.5 | C6: m | D6: link sheet Kawasan (Tesis 2.7)
A7: th (durasi hujan efektif) | B7: =Kawasan!$B$15 -> 1 | C7: jam | D7: link sheet Kawasan (Tesis 3.4.3)
A8: Q desain | B8: =Hidrolika_Pipa!$B$51 -> 0.88621393 | C8: m3/dtk | D8: link Hidrolika_Pipa (envelope)
A9: Ap hasil iterasi konvergensi | B9: 5292.5 | C9: m2 | D9: tabel hasil_desain (titik tetap iterasi Vs<->Ap) - parameter_desain.Ap_kolam dihapus (keputusan 2)
A11: KRITERIA ATENUASI Va [32]
A12: Besaran | B12: Nilai | C12: Satuan | D12: Rumus/Keterangan
A13: Va (volume atenuasi) | B13: =B8*B7*3600 -> 3190.3701 | C13: m3 | D13: Va = Q . th . 3600 [32]
A14: l (lebar kolam Va) | B14: =CEILING(SQRT(B13/B5),0.5) -> 33 | C14: m | D14: dibulatkan ke atas 0,5 m
A15: p (panjang kolam Va) | B15: =CEILING(B13/(B5*B14),0.5) -> 32.5 | C15: m
A16: Ap kriteria atenuasi | B16: =B14*B15 -> 1072.5 | C16: m2 | D16: titik awal iterasi Vs<->Ap (kolam kriteria atenuasi)
A18: NERACA & DIMENSI KOLAM (fraksi desain, basis Ap B9)
A19: Besaran | B19: Nilai | C19: Satuan | D19: Rumus/Keterangan
A20: Vs [27] | B20: =Neraca_Air!$E$524 -> 15823.567 | C20: m3 | D20: MAX defisit, sheet Neraca_Air (basis B9)
A21: V desain [33] | B21: =MAX(B20,B13) -> 15823.567 | C21: m3 | D21: maks(Vs, Va) pada titik tetap
A22: l (lebar kolam) | B22: =CEILING(SQRT(B21/B5),0.5) -> 73 | C22: m
A23: p (panjang kolam) | B23: =CEILING(B21/(B5*B22),0.5) -> 72.5 | C23: m
A24: Ap hasil desain | B24: =B22*B23 -> 5292.5 | C24: m2 | D24: Ap dimensi live - dibandingkan dgn B9 di blok cek (baris 37-42)
A25: V kolam [34] | B25: =B23*B22*B5 -> 15877.5 | C25: m3 | D25: V = p . l . he
A26: h total [35] | B26: =B5+B6 -> 3.5 | C26: m | D26: he + hf
A28: CATATAN ITERASI KONVERGENSI Vs <-> Ap (tabel hasil_desain, src/analisis_desain.py)
A29: i | B29: Ap masuk (m2) | C29: Vs (m3) | D29: V = maks(Vs,Va) | E29: l (m) | F29: p (m) | G29: Ap keluar (m2)
A30: 1 | B30: 1072.5 | C30: 12719.7 | D30: 12719.7 | E30: 65.5 | F30: 65 | G30: 4257.5
A31: 2 | B31: 4257.5 | C31: 15062.3 | D31: 15062.3 | E31: 71 | F31: 71 | G31: 5041
A32: 3 | B32: 5041 | C32: 15638.6 | D32: 15638.6 | E32: 72.5 | F32: 72 | G32: 5220
A33: 4 | B33: 5220 | C33: 15770.2 | D33: 15770.2 | E33: 73 | F33: 72.5 | G33: 5292.5
A34: 5 | B34: 5292.5 | C34: 15823.6 | D34: 15823.6 | E34: 73 | F34: 72.5 | G34: 5292.5
A35: Konvergen bila Ap keluar = Ap masuk (tercapai pada langkah 5). Nilai biru = catatan iterasi; blok neraca menghitung ulang keadaan tetap secara live.
A37: CEK KONVERGENSI ITERASI Vs <-> Ap (live vs tabel hasil_desain)
A38: Cek | B38: Nilai | C38: Satuan | D38: Keterangan
A39: Ap hasil iterasi (B9, hasil_desain) | B39: =B9 -> 5292.5 | C39: m2
